Workbook

Sheet Start Here
A1: 12-Week Developer Plan
A3: The goal | B3: Not 'know C++'. The goal: someone gives you a problem you've never seen, and you know how to figure it out.
A4: The mindset | B4: "I don't know how to do this YET. I'll investigate, break it down, experiment, and figure it out."
A5: Time | B5: 30-60 minutes a session, about 5 sessions a week. Sessions are numbered, not tied to days. Missed a day? Just carry on with the next one.
A7: The tabs
A8: Roadmap | B8: The big picture: one line per week, what you'll learn, where you're headed. Start here each week.
A9: Plan | B9: Your day-to-day list. One row = one session. Coloured bars separate the weeks.
A10: Concepts | B10: Every idea you'll meet, in plain English with an everyday example. When a Plan row mentions a word you don't know, look it up here first.
A11: Weekly Reflection | B11: 5 minutes at the end of every week.
A12: Project Review | B12: Longer reflection after each project.
A13: Resources | B13: Where to look things up, and how to search well.
A14: Progress | B14: Fills itself in from your Status column.
A16: How to do one session
A17: 1. Read (5 min) | B17: Find your next row in Plan. Read Task, What to do and Done when.
A18: 2. Learn the words (5 min) | B18: Any concept in the 'Concepts today' column you don't know? Read it in the Concepts tab. 🆕 marks a concept you're meeting for the first time.
A19: 3. Look things up (5-10 min) | B19: Answer the 'Think about' questions. Write short answers or links in Notes.
A20: 4. Plan (5 min) | B20: For anything tricky, write pseudocode in Notes before coding (template below).
A21: 5. Build (20-40 min) | B21: Do 'What to do'. ⭐ Stretch goals are only for days you have extra time.
A22: 6. Check (5 min) | B22: Go through 'Done when'. All true? Set Status to Done and fill in Minutes.
A24: Status and colours
A25: Not started / In progress | B25: It's fine for one row to take 2 sessions.
A26: Stuck | B26: Stuck for 15+ minutes. Fill in the stuck template (below) in Notes, then ask for help.
A27: Done | B27: Everything in 'Done when' is true.
A28: Level | B28: ★☆☆☆ easy · ★★☆☆ medium · ★★★☆ hard · ★★★★ challenge (expect 2 sessions)
A29: Yellow rows | B29: Checkpoints: catch up, re-check, reflect. On track? Do stretch goals instead.
A31: The 5 rules
A32: 1. Ask good questions | B32: Before asking for help, answer: What am I trying to do? What have I tried? What's the exact error? What do I think is happening? What did I look up? Can I describe the steps in plain English?
A33: 2. Research is the work | B33: Docs, Stack Overflow, articles, AI tools - all allowed. But if you use code from anywhere, you must be able to explain every line. If you can't yet, don't use it yet.
A34: 3. Pseudocode first | B34: Problem -> Input -> Expected output -> Steps in plain English -> Code -> Check.
A35: 4. Test everything | B35: Use the 7 test types below for every feature.
A36: 5. Reflect | B36: Weekly Reflection every week; Project Review after each project.
A38: Templates (copy into Notes)
A39: Stuck | B39: I'm trying to: ... I expected: ... Instead: ... (exact error message) I think the cause is: ... I tried: ... I looked up: ...
A40: Pseudocode | B40: Problem: ... Input: ... Output: ... Steps: 1. ... 2. ... 3. ... What could go wrong: ...
A42: The 7 test types
A43: Normal | B43: Typical valid input. Does the basic thing work?
A44: Invalid | B44: Wrong values: letters in a number, GPA 5.0, negative age.
A45: Empty | B45: Nothing typed. Only spaces. An empty list.
A46: Missing | B46: Search, update or delete something that doesn't exist.
A47: Duplicate | B47: The same ID twice. The same action twice.
...

Sheet Roadmap
A1: Week | B1: Project | C1: Big question | D1: By the end of the week you'll have... | E1: New concepts this week | F1: Guidance | G1: Sessions
A2: 1 | B2: Student Manager | C2: How do I turn a real-world problem into a program? | D2: A console program with a menu that adds and lists students. | E2: Requirements, Console program, Loop, Condition, Data model, Variable & type, struct, std::string, Compiler error, Single source of truth, vector, Breaking a problem down, Function, Reference vs copy, Regression test | F2: Step-by-step | G2: #1-5
A3: 2 | B3: Student Manager | C3: How does a program find, change and remove things? | D3: Search, update and delete working. | E3: Pseudocode, Algorithm, Linear search, Big-O, DRY, ID vs position, Edge case, Documentation | F3: Step-by-step | G3: #6-10
A4: 3 | B4: Student Manager | C4: What happens when users do something unexpected? | D4: An app that bad input can't break, and you can use a debugger. | E4: Testing, Boundary value, Bug report, Exception, Input validation, Business rules, const, Debugging, Debugger | F4: Step-by-step | G4: #11-15
A5: 4 | B5: Student Manager | C5: How does a program remember things after it closes? | D5: Save/load to a file, and a plan for splitting up your code. | E5: Tradeoff, Persistence, File format, File I/O, RAII, Fail loudly, Parsing, Trust boundary, Separation of concerns, Layers, Coupling & cohesion | F5: You choose how | G5: #16-20
A6: 5 | B6: Student Manager | C6: Why split code into parts? | D6: Code split into files and classes, plus your first automatic tests. | E6: Refactoring, Header & source files, Build system (CMake), Encapsulation, class, Constructor, Unit test | F6: You choose how | G6: #21-25
A7: 6 | B7: Student Manager | C7: Can I change the screen without touching the logic? | D7: A Qt window running on the same logic. Project 1 done! | E7: GUI & events, Architecture | F7: You choose how | G7: #26-30
A8: 7 | B8: Library | C8: How do different kinds of data connect? | D8: Books, members and borrowing with rules. | E8: Relationships between data, Pointer, Stack vs heap memory, State, Simplifying a problem | F8: Requirements only | G8: #31-35
A9: 8 | B9: Library | C9: How do I handle things that are similar but not the same? | D9: Waitlists, books AND DVDs, saving linked data, tests. Project 2 done! | E9: queue, map, Inheritance, Polymorphism, Smart pointer (unique_ptr), Data integrity | F9: Requirements only | G9: #36-40
A10: 9 | B10: Expense Tracker | C10: How do I turn many records into useful answers? | D10: Expenses with sorting, filtering and totals. Project 3 done! | E10: Floating-point numbers, stack, Lambda, sort, Aggregation | F10: Requirements only | G10: #41-45
A11: 10 | B11: Mini Search Engine | C11: How do I solve a problem nobody has taught me? | D11: A small search engine you researched and designed yourself. | E11: Research, Inverted index, Measuring performance, Copy vs move, unordered_map, set | F11: On your own | G11: #46-50
A12: 11 | B12: Capstone | C12: Can I plan a project myself? | D12: Your own app idea, scoped, designed and half built. | E12: Project scope | F12: On your own | G12: #51-55
A13: 12 | B13: Capstone | C13: Can I finish, test and explain it? | D13: A finished app you can demo and explain. | E13: - | F13: On your own | G13: #56-60
A15: Guidance shrinks on purpose: step-by-step -> you choose how -> requirements only -> on your own.

Sheet Plan
A1: # | B1: Week | C1: Session | D1: Task | E1: What to do (⭐ = stretch, only if you have time) | F1: Concepts today (🆕 = first time - see Concepts tab) | G1: Think about / look up | H1: Done when... | I1: Level | J1: Status | K1: Minutes | L1: Notes / pseudocode / where I got stuck
A2: WEEK 1 · Student Manager · How do I turn a real-world problem into a program? [Step-by-step]
A3: 1 | B3: 1 | C3: 1 | D3: Understand the problem, then build a menu | E3: 1. Create requirements.txt. Describe the 5 features (add, view, search, update, delete) in YOUR OWN words. 2. For each feature write: what the user gives the program (input) and what they get back (output). 3. Create a new C++ console project called StudentManager. 4. Make it show a numbered menu (1 Add, 2 View all, 3 Search, 4 Update, 5 Delete, 0 Exit), read the choice and print 'You chose: Add' etc. 5. Show the menu again after each choice, until the user picks 0. ⭐ Stretch: draw the menu screens on paper first. | F3: 🆕 Requirements 🆕 Console program 🆕 Loop 🆕 Condition | G3: What's the difference between WHAT a program must do and HOW it does it? Which kind of loop fits 'keep going until the user says stop'? | H3: requirements.txt has 5 features, each with input + output. The menu keeps coming back until you pick 0. Check: every option; a number that isn't on the menu (like 7). | I3: ★☆☆☆ | J3: Not started
A4: 2 | B4: 1 | C4: 2 | D4: Describe a student in code | E4: 1. A student has: ID, name, age, major, GPA. For each, decide what kind of value it is - whole number, decimal or text? Write your reasons in requirements.txt. 2. Create your own Student type that groups these 5 values together. 3. When the user picks 'Add', ask for each value, fill in a Student, and print it back neatly. ⭐ Stretch: write a function that turns a Student into one neat line of text. | F4: 🆕 Data model 🆕 Variable & type 🆕 struct 🆕 std::string 🆕 Compiler error | G4: Why is age a whole number but GPA a decimal? Type a name with a space (e.g. 'Priya Sharma'). What happens? Why? | H4: Add asks for all 5 values and prints them back correctly. Check: a name with a space; GPA 0 and 4; a long major name. | I4: ★☆☆☆ | J4: Not started
A5: 3 | B5: 1 | C5: 3 | D5: Remember many students | E5: Right now the program forgets a student as soon as you add the next one. 1. Find a way to keep a LIST of students that grows each time you add someone. (Look up 'vector' in the Concepts tab.) 2. 'Add' puts the new student into the list. 3. 'View all' prints every student, one per line. 4. If there are no students, 'View all' says 'No students yet.' ⭐ Stretch: print the students as a neat table with lined-up columns. | F5: 🆕 vector 🆕 Single source of truth | G5: Why not just make 100 separate Student variables? How do you go through every item in a list, one by one? | H5: Add 5 students; View all shows all 5 in the order added. View all with no students shows the friendly message. | I5: ★★☆☆ | J5: Not started
A6: 4 | B6: 1 | C6: 4 | D6: Split main() into functions | E6: Your main() is getting long and hard to read. 1. List the separate jobs main() does (show menu, add a student, print all...). 2. Move each job into its own function with a clear name, e.g. addStudent, printAllStudents. 3. main() should become short: show menu, read choice, call the right function. 4. Some functions need the student list. Find out how to give them the list WITHOUT making a copy. ⭐ Stretch: no function longer than 20 lines. | F6: 🆕 Breaking a problem down 🆕 Function 🆕 Reference vs copy | G6: What makes a good function name? If addStudent gets a COPY of the list, what happens to the student you add? | H6: main() fits on one screen. Each function does one job and its name says what. Add and View all still work exactly as before. | I6: ★★☆☆ | J6: Not started
A7: 5 | B7: 1 | C7: 5 | D7: Checkpoint: catch up, re-test, reflect | E7: 1. Anything this week not 'Done'? Finish that first. 2. Re-run the checks in 'Done when' for every session this week. 3. Make sure you can add 5 students and see them all. 4. Make a backup copy of your project folder called StudentManager_W1. 5. Fill in this week's row in the Weekly Reflection tab. Ahead of schedule? Do a ⭐ stretch goal from earlier. | F7: 🆕 Regression test | G7: What was the most useful thing you looked up this week? Paste the link in Notes. | H7: Every session this week is Done (or Notes say why not). 5 students add and show correctly. Backup made. Reflection written. | I7: ★☆☆☆ | J7: Not started
A8: WEEK 2 · Student Manager · How does a program find, change and remove things? [Step-by-step]
A9: 6 | B9: 2 | C9: 1 | D9: Find a student by ID | E9: PSEUDOCODE FIRST: write the steps in Notes using the template on Start Here. 1. Add a menu option 'Search by ID'. 2. Write a function that looks through the list and gives back WHERE the student is (their position), or a special value meaning 'not found'. 3. Print the student, or 'No student with ID 105'. ⭐ Stretch: count how many students your search checked, and print it. | F9: 🆕 Pseudocode 🆕 Algorithm 🆕 Linear search 🆕 Big-O | G9: With 1 million students, how many would you check in the worst case? What should the function give back when nothing is found? | H9: Pseudocode is in Notes (written BEFORE the code). Check: first student, last student, an ID that doesn't exist, an empty list. | I9: ★★☆☆ | J9: Not started
A10: 7 | B10: 2 | C10: 2 | D10: Search by part of a name | E10: Typing 'pri' should find 'Priya' AND 'PRINCE'. 1. Split this into two smaller problems: (a) make upper/lower case not matter, (b) check whether one piece of text contains another. 2. Solve each small problem in its own function. Test each one alone. 3. Combine them: print EVERY student whose name matches. ⭐ Stretch: search the major too. | F10: Breaking a problem down | G10: How can 'Pri' and 'pri' be compared as equal? How do you check if one string contains another in C++? | H10: Shows all matches, not just the first. Check: 'PRI', 'pri', a letter from the middle of a name, no matches, empty search. | I10: ★★☆☆ | J10: Not started
A11: 8 | B11: 2 | C11: 3 | D11: Update a student | E11: 1. Ask for an ID and find the student (reuse your search function!). 2. Show their current details, then ask for new values. 3. Save the changes into the list. 4. If 'View all' still shows the OLD values, stop and investigate: are you changing the real student, or a copy? ⭐ Stretch: pressing Enter without typing keeps the old value. | F11: Reference vs copy 🆕 DRY | G11: What's the difference between Student s = list[i]; and Student& s = list[i]; ? | H11: Changes show up in View all. In Notes, explain copy vs reference in your own words. Check: update an ID that doesn't exist; change every field. | I11: ★★★☆ | J11: Not started
A12: 9 | B12: 2 | C12: 4 | D12: Delete a student | E12: 1. Ask for an ID and find the student. 2. Ask 'Are you sure? (y/n)'. 3. Remove them from the list. 4. Before running it, predict: after deleting the 2nd of 4 students, what position is the old 3rd student in now? ⭐ Stretch: 'Delete all students' with a double confirmation. | F12: 🆕 ID vs position 🆕 Edge case | G12: How do you remove an item from the middle of a vector? Why is 'delete student ID 105' safer than 'delete the 3rd student'? | H12: The right student is removed. Check: first, last and middle student; missing ID; answering 'n'; deleting the only student. | I12: ★★☆☆ | J12: Not started
A13: 10 | B13: 2 | C13: 5 | D13: Checkpoint: catch up, re-test, reflect | E13: 1. Anything this week not 'Done'? Finish that first. 2. Re-run the checks in 'Done when' for every session this week. 3. Write README.txt: what the app does and how to use each feature. 4. Make a backup copy of your project folder called StudentManager_V1. 5. Fill in this week's row in the Weekly Reflection tab. Ahead of schedule? Do a ⭐ stretch goal from earlier. | F13: Regression test 🆕 Documentation | G13: What was the most useful thing you looked up this week? Paste the link in Notes. | H13: Every session this week is Done (or Notes say why not). Add, search, update and delete all work. README.txt exists. Backup made. Reflection written. | I13: ★☆☆☆ | J13: Not started
A14: WEEK 3 · Student Manager · What happens when users do something unexpected? [Step-by-step]
A15: 11 | B15: 3 | C15: 1 | D15: Try to break your own app (no coding today!) | E15: Be a user who makes mistakes - or who is trying to break things. 1. Use the 7 test types on the Start Here tab. 2. Try at least 15 things. For each, write in bugs.txt: what I did -> what happened -> what SHOULD happen. 3. Don't fix anything today. Just collect. Must try: typing a letter when it asks for age. ⭐ Stretch: rank the 3 bugs a real user would hate most. | F15: 🆕 Testing Edge case 🆕 Boundary value 🆕 Bug report | G15: What does 'boundary value' mean for GPA (0.0 to 4.0)? Which exact values should you try? | H15: bugs.txt has 15+ entries, each with: steps, what happened, what should happen. | I15: ★☆☆☆ | J15: Not started
A16: 12 | B16: 3 | C16: 2 | D16: Read numbers safely | E16: You probably found that typing letters where a number is expected breaks the program badly. 1. Research WHY that happens. 2. Write ONE helper function that asks a question and keeps asking until the user types a valid whole number in a range, e.g. readInt("Age: ", 16, 100). 3. Make similar helpers for decimals (GPA) and for non-empty text (name). 4. Use these helpers everywhere you read input, including the menu. ⭐ Stretch: reject '12abc' and '3.5' when a whole number is expected. | F16: 🆕 Input validation 🆕 Exception DRY | G16: What happens to std::cin when it can't read a number? What does std::stoi do when given 'abc'? | H16: No input can crash or freeze the app. Check: letters, empty, -5, 999, 3.5 for age, only spaces. Mark the fixed bugs in bugs.txt. | I16: ★★★☆ | J16: Not started
A17: 13 | B17: 3 | C17: 3 | D17: Rules: valid students and unique IDs | E17: Some rules aren't about typing, they're about the data itself. 1. Write every rule for a valid student (e.g. name not blank, GPA 0-4, ID not already used). 2. Write ONE function that checks a student against all rules and returns a message saying what's wrong (or nothing if it's fine). 3. Use it in both Add and Update. 4. Careful with Update: a student keeping their OWN ID is fine. ⭐ Stretch: show ALL problems at once, not just the first. | F17: 🆕 Business rules 🆕 const | G17: Why keep all the rules in one function instead of checking separately in Add and Update? Why is 'update student 101 but keep ID 101' a tricky case? | H17: Duplicate IDs are impossible. Check: add a duplicate ID (fails); update keeping own ID (works); update to another student's ID (fails); update to a new free ID (works). | I17: ★★★☆ | J17: Not started
A18: 14 | B18: 3 | C18: 4 | D18: Use the debugger | E18: Print statements only get you so far. A debugger lets you pause the program and look inside. 1. Find how to set a breakpoint (in Qt Creator: click left of a line number). 2. Put one in your search function. Run in Debug mode. 3. Step through line by line. Watch the variables change. 4. Ask your mentor for a 'mystery bug' (or pick one from bugs.txt) and find it using ONLY the debugger. ⭐ Stretch: use the call stack to see which function called which. | F18: 🆕 Debugger 🆕 Debugging | G18: What's the difference between 'Step Over' and 'Step Into'? What does the call stack show? | H18: You found a bug using breakpoints and stepping. In Notes: what you expected, what you saw, what the cause was. | I18: ★★☆☆ | J18: Not started
A19: 15 | B19: 3 | C19: 5 | D19: Checkpoint: catch up, re-test, reflect | E19: 1. Anything this week not 'Done'? Finish that first. 2. Re-run the checks in 'Done when' for every session this week. 3. Re-try every entry in bugs.txt and mark each Fixed / Not fixed. 4. Make a backup copy of your project folder called StudentManager_V2. 5. Fill in this week's row in the Weekly Reflection tab. Ahead of schedule? Do a ⭐ stretch goal from earlier. | F19: Regression test | G19: What was the most useful thing you looked up this week? Paste the link in Notes. | H19: Every session this week is Done (or Notes say why not). Every bugs.txt entry is marked. Backup made. Reflection written. | I19: ★☆☆☆ | J19: Not started
A20: WEEK 4 · Student Manager · How does a program remember things after it closes? [You choose how]
A21: 16 | B21: 4 | C21: 1 | D21: Design how to save students (no coding) | E21: When the program closes, every student is lost. You'll fix that by saving to a file. Today, design only: 1. By hand, write 2 students into students.txt in a layout you like (e.g. one student per line). 2. What separates the values? What if a name contains that character? 3. When do you save: after every change, or on Exit? When do you load? 4. Write your choices and reasons in design_storage.txt. | F21: 🆕 Persistence 🆕 File format 🆕 Tradeoff | G21: What is a CSV file? What goes wrong with the name 'Smith, John' in a CSV? What's the risk of only saving on Exit? | H21: design_storage.txt explains your format and when you save/load, with reasons. A hand-written students.txt exists. | I21: ★★☆☆ | J21: Not started
A22: 17 | B22: 4 | C22: 2 | D22: Save students to a file | E22: Save all students into a file using your format. Plan your own steps in Notes first. Rule: if the file can't be opened, tell the user. Never fail silently. ⭐ Stretch: save to a temporary file first, then rename it - so a crash can't leave a half-written file. | F22: 🆕 File I/O 🆕 Fail loudly 🆕 RAII | G22: How do you write to a file in C++? How do you know if opening the file failed? When does the file get closed? (Look up RAII.) | H22: Open the file in a text editor: every student is there and correct. Check: 0 students, 10 students, a name containing your separator character. | I22: ★★☆☆ | J22: Not started
A23: 18 | B23: 4 | C23: 3 | D23: Load students from the file | E23: When the program starts, load the students back. Before coding, think about bad cases: no file yet (first run), a line with missing values, age written as 'abc', a duplicate ID in the file. Plan your own steps. | F23: 🆕 Parsing 🆕 Trust boundary | G23: How do you split one line of text into pieces in C++? Should one bad line stop ALL students from loading? Can you reuse your rules function from week 3? | H23: Close and reopen: your data is back. Check: first run with no file; hand-edit the file to break a line in each of the ways above. Clear message, no crash. | I23: ★★★☆ | J23: Not started
A24: 19 | B24: 4 | C24: 4 | D24: Audit: what is main.cpp doing? | E24: 1. Count the lines in main.cpp. 2. List EVERY job it does: showing menus, reading input, checking rules, searching, saving files... 3. Sort the jobs into 4 boxes: - Screen (talking to the user) - Rules (what's allowed) - Data (what a student is) - Storage (files) 4. Draw the boxes with arrows showing who uses whom. Save as architecture.txt or a photo. | F24: 🆕 Separation of concerns 🆕 Layers 🆕 Coupling & cohesion | G24: If you wanted a WINDOW app instead of a console app, which of your code could stay exactly the same? If you switched from a text file to a database, which code would change? | H24: Every function is in a box. The drawing is done. You can explain in 2 sentences why the boxes exist. | I24: ★★☆☆ | J24: Not started
A25: 20 | B25: 4 | C25: 5 | D25: Checkpoint: catch up, re-test, reflect | E25: 1. Anything this week not 'Done'? Finish that first. 2. Re-run the checks in 'Done when' for every session this week. 3. Close and reopen the app several times with different data - nothing lost? 4. Make a backup copy of your project folder called StudentManager_V3. 5. Fill in this week's row in the Weekly Reflection tab. Ahead of schedule? Do a ⭐ stretch goal from earlier. | F25: Regression test | G25: What was the most useful thing you looked up this week? Paste the link in Notes. | H25: Every session this week is Done (or Notes say why not). Save/load reliable. architecture.txt done. Backup made. Reflection written. | I25: ★☆☆☆ | J25: Not started
A26: WEEK 5 · Student Manager · Why split code into parts? [You choose how]
A27: 21 | B27: 5 | C27: 1 | D27: Move Student into its own files | E27: Create Student.h and Student.cpp and move the Student type into them. 1. Find out what belongs in a .h file and what belongs in a .cpp file. 2. Tell the build system about the new files (CMakeLists.txt). 3. Fix compile errors one at a time, starting from the TOP of the list. The program must behave exactly the same as before. | F27: 🆕 Header & source files 🆕 Build system (CMake) 🆕 Refactoring | G27: Why do C++ projects split code into .h and .cpp files? What does #pragma once prevent? | H27: Student lives in its own files. Regression check: run everything in bugs.txt - all still behaves the same. | I27: ★★★☆ | J27: Not started
A28: 22 | B28: 5 | C28: 2 | D28: Turn the rules into a StudentService class | E28: Create a class StudentService that OWNS the student list and offers: add, update, remove, findById, searchByName. 1. The list is private: only the service can change it. 2. Your rules function moves in too. 3. The service must NEVER print or read from the console. It returns results and error messages instead. 4. main.cpp now asks the service to do things. | F28: 🆕 class 🆕 Encapsulation 🆕 Constructor | G28: Why make the list private? If the service can't print, how does it tell main.cpp that something went wrong? | H28: No rules or searching left in main.cpp. StudentService.cpp contains no std::cout or std::cin. Everything works as before. | I28: ★★★☆ | J28: Not started
A29: 23 | B29: 5 | C29: 3 | D29: Move saving/loading into StudentStorage | E29: Create StudentStorage with save and load. Then organize folders: models/ (Student) services/ (StudentService) storage/ (StudentStorage) ui/ (the console menu) You decide: who calls storage - the menu or the service? Write down why. | F29: Layers | G29: Who should decide WHEN to save, and who should decide HOW? | H29: 4 folders, each with the right files. main.cpp is short. Everything works, including save and load. | I29: ★★★☆ | J29: Not started
A30: 24 | B30: 5 | C30: 4 | D30: Prove it: test the rules without the menu | E30: Because the rules no longer need the console, you can test them automatically. 1. Create a second small program, tests.cpp, that uses StudentService directly - no menu. 2. Write at least 8 checks, e.g. 'adding a duplicate ID is rejected', 'searching pri finds Priya'. Print PASS or FAIL for each. 3. Break a rule on purpose inside StudentService. Does a test catch it? | F30: 🆕 Unit test | G30: What is a unit test? How do you add a second program (executable) in CMakeLists.txt? | H30: 8+ checks run in one go and all pass. A deliberate bug was caught by a test. | I30: ★★★☆ | J30: Not started
A31: 25 | B31: 5 | C31: 5 | D31: Checkpoint: catch up, re-test, reflect | E31: 1. Anything this week not 'Done'? Finish that first. 2. Re-run the checks in 'Done when' for every session this week. 3. Update README.txt with your architecture drawing and one paragraph on why it's split this way. 4. Make a backup copy of your project folder called StudentManager_V4. 5. Fill in this week's row in the Weekly Reflection tab. Ahead of schedule? Do a ⭐ stretch goal from earlier. | F31: Regression test Documentation | G31: What was the most useful thing you looked up this week? Paste the link in Notes. | H31: Every session this week is Done (or Notes say why not). README explains the structure. Tests pass. Backup made. Reflection written. | I31: ★☆☆☆ | J31: Not started
A32: WEEK 6 · Student Manager · Can I change the screen without touching the logic? [You choose how]
A33: 26 | B33: 6 | C33: 1 | D33: Put a window on top of your logic | E33: Time to use your Qt skills. Create a Qt Widgets project that uses your models/, services/ and storage/ folders UNCHANGED. 1. Show a window with a table of all students loaded from your file. 2. Rule for this week: only edit files in ui/. If you must change anything else, write down why in Notes. | F33: 🆕 GUI & events | G33: How can a Qt project use source files from other folders? In a console app YOU control the order of things. Who controls it in a window app? | H33: The window shows the students from your saved file. No files outside ui/ changed (or each change is explained). | I33: ★★★☆ | J33: Not started
A34: 27 | B34: 6 | C34: 2 | D34: Add students from the window | E34: A form (ID, name, age, major, GPA) and an Add button. Show the service's error messages in a message box. Refresh the table after each add. | F34: Single source of truth | G34: Where should the error message text come from - the window or the service? Why? | H34: Adding works, and every rule from week 3 applies without being rewritten. | I34: ★★☆☆ | J34: Not started
A35: 28 | B35: 6 | C35: 3 | D35: Search, update and delete in the window | E35: Bring the other 3 features to the window. Selecting a row should fill the form for editing. | F35: ID vs position | G35: If the table is filtered by a search, does row 2 still mean the 3rd student in the list? | H35: All 5 features work in the window. Check: delete while a search filter is showing - is the RIGHT student deleted? | I35: ★★★☆ | J35: Not started
A36: 29 | B36: 6 | C36: 4 | D36: Compare: one brain, two faces | E36: Your console app and your window app now run on the SAME logic. 1. Run tests.cpp - still passing? 2. Count how many lines you changed outside ui/ this week. 3. Write a short note: what would have happened if you'd built the window app in week 1 with all the logic inside the window? | F36: 🆕 Architecture | G36: Where do real companies do this? (Think of a bank with a website AND a phone app.) | H36: Both apps work. Tests pass. Note written. | I36: ★☆☆☆ | J36: Not started
A37: 30 | B37: 6 | C37: 5 | D37: Checkpoint: catch up, re-test, reflect | E37: 1. Anything this week not 'Done'? Finish that first. 2. Re-run the checks in 'Done when' for every session this week. 3. Write in README.txt how the console and window apps share the same logic. 4. Make a backup copy of your project folder called StudentManager_Final. 5. Fill in the Project Review tab for this project (all 8 questions). Ahead of schedule? Do a ⭐ stretch goal from earlier. | F37: Regression test Documentation | G37: What was the most useful thing you looked up this week? Paste the link in Notes. | H37: Every session this week is Done (or Notes say why not). Both apps work. Project Review for Student Manager filled in. Backup made. Reflection written. | I37: ★☆☆☆ | J37: Not started
A38: WEEK 7 · Library · How do different kinds of data connect? [Requirements only]
A39: 31 | B39: 7 | C39: 1 | D39: Library: requirements and data design | E39: A small library lends books to members. Requirements: add books (ID, title, author) and members (ID, name). Members borrow and return books. A member can have at most 3 books. The app shows who has what. 1. List the kinds of things (entities) and their information. 2. Draw how they connect. A borrowing (a 'loan') links a book and a member. 3. Decide: should a loan store the book's ID, or a pointer to the book? Research both, write your decision. 4. Decide: console or Qt? Your call. | F39: 🆕 Relationships between data 🆕 Pointer 🆕 Stack vs heap memory | G39: What is a pointer? What happens to a pointer to an item in a vector when the vector grows? Can you save a pointer into a file and load it back? | H39: design.txt with entities, a drawing, and the IDs-vs-pointers decision with reasons. | I39: ★★☆☆ | J39: Not started
A40: 32 | B40: 7 | C40: 2 | D40: Library: set up, books and members | E40: Start with the 4 folders from day 1 (models, services, storage, ui). Add and list books and members, with rules (no duplicate IDs, no blank names). Plan your own steps. | F40: - | G40: What did you do in the Student Manager that you'd do differently now? | H40: Books and members can be added and listed, with rules. The structure is in place. | I40: ★★☆☆ | J40: Not started
...

Sheet Concepts
A1: # | B1: Concept | C1: Type | D1: In plain English | E1: Everyday example | F1: Why developers care | G1: First met in session | H1: Used again in | I1: Learn more
A2: 1 | B2: Requirements | C2: Thinking | D2: A clear list of what the program must do, from the user's point of view. | E2: A shopping list says 'milk', not 'drive down Main St to the store'. | F2: If you don't know exactly what to build, you'll build the wrong thing. | G2: #1 | H2: - | I2: Search: 'software requirements for beginners'
A3: 2 | B3: Console program | C3: Design | D3: A text-only program: it prints text and reads what you type. | E3: Texting back and forth with the program. | F3: Lets you focus on logic without designing screens. | G3: #1 | H3: - | I3: -
A4: 3 | B4: Loop | C4: C++ | D4: Repeating code while something is true, or once for each item in a list. | E4: Keep stirring until the sauce thickens. | F4: Almost every program repeats something. | G4: #1 | H4: - | I4: https://www.learncpp.com/
A5: 4 | B5: Condition | C5: C++ | D5: Running code only if a test is true (if / else / switch). | E5: If it's raining, take an umbrella. | F5: Programs make decisions. | G5: #1 | H5: - | I5: https://www.learncpp.com/
A6: 5 | B6: Data model | C6: Design | D6: Deciding what information your program stores, and what kind each piece is. | E6: A contact card: name (text), phone (digits), birthday (date). | F6: Bad data design makes every later feature harder. | G6: #2 | H6: - | I6: Search: 'data modeling basics'
A7: 6 | B7: Variable & type | C7: C++ | D7: A named box holding a value. The type says what kind: whole number (int), decimal (double), text (string)... | E7: Labelled jars: you don't pour milk into the sugar jar. | F7: The right type prevents whole groups of bugs. | G7: #2 | H7: - | I7: https://www.learncpp.com/
A8: 7 | B8: struct | C8: C++ | D8: Your own type that groups related values together under one name. | E8: A form with fields: name, age, major. | F8: Keeps related data together instead of loose variables. | G8: #2 | H8: - | I8: https://www.learncpp.com/
A9: 8 | B9: std::string | C9: C++ | D9: C++'s type for text. | E9: A line of writing. | F9: Names, messages, file contents - most programs handle lots of text. | G9: #2 | H9: - | I9: https://en.cppreference.com/w/cpp/string/basic_string
A10: 9 | B10: Compiler error | C10: C++ | D10: The compiler telling you your code isn't valid C++. Always read the FIRST error first. | E10: A spell-checker underlining a word. | F10: The first error often causes the rest. Reading errors calmly is a core skill. | G10: #2 | H10: - | I10: -
A11: 10 | B11: Single source of truth | C11: Design | D11: Keep each fact in exactly ONE place; everything else reads from there. | E11: One shared family calendar instead of everyone keeping their own copy. | F11: Two copies of a fact eventually disagree - and that's a bug. | G11: #3 | H11: #27 | I11: -
A12: 11 | B12: vector | C12: Data structures & algorithms | D12: A list that grows as you add items and keeps them in order. Written std::vector<Student>. | E12: A notebook where you can keep adding pages. | F12: The go-to C++ container for 'many of something'. | G12: #3 | H12: - | I12: https://en.cppreference.com/w/cpp/container/vector
A13: 12 | B13: Breaking a problem down | C13: Thinking | D13: Splitting a big problem into small problems you can solve one at a time. | E13: 'Cook dinner' -> buy food, chop, cook, serve. | F13: Every hard problem is a pile of easy ones. | G13: #4 | H13: #7 | I13: Search: 'problem decomposition programming'
... A76: 75 | B76: Project scope | C76: Thinking | D76: Deciding what you WILL and WON'T build. | E76: Planning a 3-day trip: you can't see every city. | F76: Small and finished beats huge and half-done. | G76: #51 | H76: - | I76: Search: 'MVP minimum viable product'

Sheet Weekly Reflection
A1: Week | B1: Project | C1: What did I build? | D1: What was hard? | E1: What did I look up? | F1: A mistake I made (and how I found it) | G1: What I learned | H1: Confidence (1-5)
A2: 1 | B2: Student Manager
A3: 2 | B3: Student Manager
A4: 3 | B4: Student Manager
A5: 4 | B5: Student Manager
A6: 5 | B6: Student Manager
A7: 6 | B7: Student Manager
A8: 7 | B8: Library
A9: 8 | B9: Library
A10: 9 | B10: Expense Tracker
A11: 10 | B11: Mini Search Engine
A12: 11 | B12: Capstone
A13: 12 | B13: Capstone

Sheet Project Review
A1: Question | B1: Student Manager | C1: Library | D1: Expense Tracker | E1: Mini Search Engine | F1: Capstone
A2: 1. What did I build?
A3: 2. What was difficult?
A4: 3. What did I research?
A5: 4. What mistakes did I make?
A6: 5. What did I learn?
A7: 6. What would I change if I rebuilt it?
A8: 7. Why did I choose this structure / these containers?
A9: 8. What would happen if the app became 10x larger?

Sheet Resources
A1: Resource | B1: Link | C1: Use it for
A2: learncpp.com | B2: https://www.learncpp.com/ | C2: Beginner-friendly C++ lessons. Best first stop when a concept is new.
A3: cppreference | B3: https://en.cppreference.com/w/cpp | C3: The exact C++ reference. Dense - scroll to the Example at the bottom first.
A4: Qt 6 documentation | B4: https://doc.qt.io/qt-6/ | C4: Every Qt class (from week 6). Search the class name and read 'Detailed Description'.
A5: Qt Creator debugging | B5: https://doc.qt.io/qtcreator/creator-debugging.html | C5: Breakpoints and stepping (week 3).
A6: Stack Overflow | B6: https://stackoverflow.com/questions/tagged/c%2b%2b | C6: Search your exact error message. Read the question AND the top answers.
A7: Project Gutenberg | B7: https://www.gutenberg.org/ | C7: Free text files for the week 10 search engine.
A8: AI tools | B8: (ChatGPT, Claude, ...) | C8: Great for explaining errors and concepts. Rule: never keep code you can't explain line by line.
A10: How to search well
A11: • Paste the exact error message (remove your own file paths and variable names).
A12: • Add 'C++' to your search.
A13: • Try learncpp.com first; use cppreference when you need exact details.
A14: • Found something useful? Put the link in the Notes column so you can find it again.

Sheet Progress
A1: Week | B1: Project | C1: Big question | D1: Sessions | E1: Done | F1: Stuck | G1: % done | H1: Progress | I1: Minutes
A2: 1 | B2: Student Manager | C2: How do I turn a real-world problem into a program? | D2: =COUNTIF(Plan!$B$2:$B$73,A2) | E2: =COUNTIFS(Plan!$B$2:$B$73,A2,Plan!$J$2:$J$73,"Done") | F2: =COUNTIFS(Plan!$B$2:$B$73,A2,Plan!$J$2:$J$73,"Stuck") | G2: =IF(D2=0,0,E2/D2) | H2: =REPT("█",ROUND(G2*10,0))&REPT("░",10-ROUND(G2*10,0)) | I2: =SUMIF(Plan!$B$2:$B$73,A2,Plan!$K$2:$K$73)
A3: 2 | B3: Student Manager | C3: How does a program find, change and remove things? | D3: =COUNTIF(Plan!$B$2:$B$73,A3) | E3: =COUNTIFS(Plan!$B$2:$B$73,A3,Plan!$J$2:$J$73,"Done") | F3: =COUNTIFS(Plan!$B$2:$B$73,A3,Plan!$J$2:$J$73,"Stuck") | G3: =IF(D3=0,0,E3/D3) | H3: =REPT("█",ROUND(G3*10,0))&REPT("░",10-ROUND(G3*10,0)) | I3: =SUMIF(Plan!$B$2:$B$73,A3,Plan!$K$2:$K$73)
A4: 3 | B4: Student Manager | C4: What happens when users do something unexpected? | D4: =COUNTIF(Plan!$B$2:$B$73,A4) | E4: =COUNTIFS(Plan!$B$2:$B$73,A4,Plan!$J$2:$J$73,"Done") | F4: =COUNTIFS(Plan!$B$2:$B$73,A4,Plan!$J$2:$J$73,"Stuck") | G4: =IF(D4=0,0,E4/D4) | H4: =REPT("█",ROUND(G4*10,0))&REPT("░",10-ROUND(G4*10,0)) | I4: =SUMIF(Plan!$B$2:$B$73,A4,Plan!$K$2:$K$73)
A5: 4 | B5: Student Manager | C5: How does a program remember things after it closes? | D5: =COUNTIF(Plan!$B$2:$B$73,A5) | E5: =COUNTIFS(Plan!$B$2:$B$73,A5,Plan!$J$2:$J$73,"Done") | F5: =COUNTIFS(Plan!$B$2:$B$73,A5,Plan!$J$2:$J$73,"Stuck") | G5: =IF(D5=0,0,E5/D5) | H5: =REPT("█",ROUND(G5*10,0))&REPT("░",10-ROUND(G5*10,0)) | I5: =SUMIF(Plan!$B$2:$B$73,A5,Plan!$K$2:$K$73)
A6: 5 | B6: Student Manager | C6: Why split code into parts? | D6: =COUNTIF(Plan!$B$2:$B$73,A6) | E6: =COUNTIFS(Plan!$B$2:$B$73,A6,Plan!$J$2:$J$73,"Done") | F6: =COUNTIFS(Plan!$B$2:$B$73,A6,Plan!$J$2:$J$73,"Stuck") | G6: =IF(D6=0,0,E6/D6) | H6: =REPT("█",ROUND(G6*10,0))&REPT("░",10-ROUND(G6*10,0)) | I6: =SUMIF(Plan!$B$2:$B$73,A6,Plan!$K$2:$K$73)
A7: 6 | B7: Student Manager | C7: Can I change the screen without touching the logic? | D7: =COUNTIF(Plan!$B$2:$B$73,A7) | E7: =COUNTIFS(Plan!$B$2:$B$73,A7,Plan!$J$2:$J$73,"Done") | F7: =COUNTIFS(Plan!$B$2:$B$73,A7,Plan!$J$2:$J$73,"Stuck") | G7: =IF(D7=0,0,E7/D7) | H7: =REPT("█",ROUND(G7*10,0))&REPT("░",10-ROUND(G7*10,0)) | I7: =SUMIF(Plan!$B$2:$B$73,A7,Plan!$K$2:$K$73)
A8: 7 | B8: Library | C8: How do different kinds of data connect? | D8: =COUNTIF(Plan!$B$2:$B$73,A8) | E8: =COUNTIFS(Plan!$B$2:$B$73,A8,Plan!$J$2:$J$73,"Done") | F8: =COUNTIFS(Plan!$B$2:$B$73,A8,Plan!$J$2:$J$73,"Stuck") | G8: =IF(D8=0,0,E8/D8) | H8: =REPT("█",ROUND(G8*10,0))&REPT("░",10-ROUND(G8*10,0)) | I8: =SUMIF(Plan!$B$2:$B$73,A8,Plan!$K$2:$K$73)
A9: 8 | B9: Library | C9: How do I handle things that are similar but not the same? | D9: =COUNTIF(Plan!$B$2:$B$73,A9) | E9: =COUNTIFS(Plan!$B$2:$B$73,A9,Plan!$J$2:$J$73,"Done") | F9: =COUNTIFS(Plan!$B$2:$B$73,A9,Plan!$J$2:$J$73,"Stuck") | G9: =IF(D9=0,0,E9/D9) | H9: =REPT("█",ROUND(G9*10,0))&REPT("░",10-ROUND(G9*10,0)) | I9: =SUMIF(Plan!$B$2:$B$73,A9,Plan!$K$2:$K$73)
A10: 9 | B10: Expense Tracker | C10: How do I turn many records into useful answers? | D10: =COUNTIF(Plan!$B$2:$B$73,A10) | E10: =COUNTIFS(Plan!$B$2:$B$73,A10,Plan!$J$2:$J$73,"Done") | F10: =COUNTIFS(Plan!$B$2:$B$73,A10,Plan!$J$2:$J$73,"Stuck") | G10: =IF(D10=0,0,E10/D10) | H10: =REPT("█",ROUND(G10*10,0))&REPT("░",10-ROUND(G10*10,0)) | I10: =SUMIF(Plan!$B$2:$B$73,A10,Plan!$K$2:$K$73)
A11: 10 | B11: Mini Search Engine | C11: How do I solve a problem nobody has taught me? | D11: =COUNTIF(Plan!$B$2:$B$73,A11) | E11: =COUNTIFS(Plan!$B$2:$B$73,A11,Plan!$J$2:$J$73,"Done") | F11: =COUNTIFS(Plan!$B$2:$B$73,A11,Plan!$J$2:$J$73,"Stuck") | G11: =IF(D11=0,0,E11/D11) | H11: =REPT("█",ROUND(G11*10,0))&REPT("░",10-ROUND(G11*10,0)) | I11: =SUMIF(Plan!$B$2:$B$73,A11,Plan!$K$2:$K$73)
A12: 11 | B12: Capstone | C12: Can I plan a project myself? | D12: =COUNTIF(Plan!$B$2:$B$73,A12) | E12: =COUNTIFS(Plan!$B$2:$B$73,A12,Plan!$J$2:$J$73,"Done") | F12: =COUNTIFS(Plan!$B$2:$B$73,A12,Plan!$J$2:$J$73,"Stuck") | G12: =IF(D12=0,0,E12/D12) | H12: =REPT("█",ROUND(G12*10,0))&REPT("░",10-ROUND(G12*10,0)) | I12: =SUMIF(Plan!$B$2:$B$73,A12,Plan!$K$2:$K$73)
A13: 12 | B13: Capstone | C13: Can I finish, test and explain it? | D13: =COUNTIF(Plan!$B$2:$B$73,A13) | E13: =COUNTIFS(Plan!$B$2:$B$73,A13,Plan!$J$2:$J$73,"Done") | F13: =COUNTIFS(Plan!$B$2:$B$73,A13,Plan!$J$2:$J$73,"Stuck") | G13: =IF(D13=0,0,E13/D13) | H13: =REPT("█",ROUND(G13*10,0))&REPT("░",10-ROUND(G13*10,0)) | I13: =SUMIF(Plan!$B$2:$B$73,A13,Plan!$K$2:$K$73)
A14: Total | D14: =SUM(D2:D13) | E14: =SUM(E2:E13) | F14: =SUM(F2:F13) | G14: =IF(D14=0,0,E14/D14) | H14: =REPT("█",ROUND(G14*10,0))&REPT("░",10-ROUND(G14*10,0)) | I14: =SUM(I2:I13)
C15: Hours spent in total: | I15: =ROUND(I14/60,1)
